2023-05-05 22:07:30,883 [INFO] junblog: INFO 레벨로 출력
2023-05-05 22:07:30,899 [ERROR] django.request: Internal Server Error: /
Traceback (most recent call last):
  File "/home/ubuntu/venvs/myproject/lib/python3.8/site-packages/django/db/backends/utils.py", line 89, in _execute
    return self.cursor.execute(sql, params)
  File "/home/ubuntu/venvs/myproject/lib/python3.8/site-packages/django/db/backends/sqlite3/base.py", line 328, in execute
    return super().execute(query, params)
sqlite3.OperationalError: no such table: auth_user

The above exception was the direct cause of the following exception:

Traceback (most recent call last):
  File "/home/ubuntu/venvs/myproject/lib/python3.8/site-packages/django/core/handlers/exception.py", line 55, in inner
    response = get_response(request)
  File "/home/ubuntu/venvs/myproject/lib/python3.8/site-packages/django/core/handlers/base.py", line 197, in _get_response
    response = wrapped_callback(request, *callback_args, **callback_kwargs)
  File "/home/ubuntu/projects/JunBlog/main/view.py", line 26, in home
    posts = countpost(request)
  File "/home/ubuntu/projects/JunBlog/main/view.py", line 10, in countpost
    if request.user in User.objects.all(): # 유저가 로그인하면
  File "/home/ubuntu/venvs/myproject/lib/python3.8/site-packages/django/db/models/query.py", line 398, in __iter__
    self._fetch_all()
  File "/home/ubuntu/venvs/myproject/lib/python3.8/site-packages/django/db/models/query.py", line 1881, in _fetch_all
    self._result_cache = list(self._iterable_class(self))
  File "/home/ubuntu/venvs/myproject/lib/python3.8/site-packages/django/db/models/query.py", line 91, in __iter__
    results = compiler.execute_sql(
  File "/home/ubuntu/venvs/myproject/lib/python3.8/site-packages/django/db/models/sql/compiler.py", line 1560, in execute_sql
    cursor.execute(sql, params)
  File "/home/ubuntu/venvs/myproject/lib/python3.8/site-packages/django/db/backends/utils.py", line 67, in execute
    return self._execute_with_wrappers(
  File "/home/ubuntu/venvs/myproject/lib/python3.8/site-packages/django/db/backends/utils.py", line 80, in _execute_with_wrappers
    return executor(sql, params, many, context)
  File "/home/ubuntu/venvs/myproject/lib/python3.8/site-packages/django/db/backends/utils.py", line 89, in _execute
    return self.cursor.execute(sql, params)
  File "/home/ubuntu/venvs/myproject/lib/python3.8/site-packages/django/db/utils.py", line 91, in __exit__
    raise dj_exc_value.with_traceback(traceback) from exc_value
  File "/home/ubuntu/venvs/myproject/lib/python3.8/site-packages/django/db/backends/utils.py", line 89, in _execute
    return self.cursor.execute(sql, params)
  File "/home/ubuntu/venvs/myproject/lib/python3.8/site-packages/django/db/backends/sqlite3/base.py", line 328, in execute
    return super().execute(query, params)
django.db.utils.OperationalError: no such table: auth_user
2023-05-05 22:07:31,858 [INFO] junblog: INFO 레벨로 출력
2023-05-05 22:07:31,871 [ERROR] django.request: Internal Server Error: /
Traceback (most recent call last):
  File "/home/ubuntu/venvs/myproject/lib/python3.8/site-packages/django/db/backends/utils.py", line 89, in _execute
    return self.cursor.execute(sql, params)
  File "/home/ubuntu/venvs/myproject/lib/python3.8/site-packages/django/db/backends/sqlite3/base.py", line 328, in execute
    return super().execute(query, params)
sqlite3.OperationalError: no such table: auth_user

The above exception was the direct cause of the following exception:

Traceback (most recent call last):
  File "/home/ubuntu/venvs/myproject/lib/python3.8/site-packages/django/core/handlers/exception.py", line 55, in inner
    response = get_response(request)
  File "/home/ubuntu/venvs/myproject/lib/python3.8/site-packages/django/core/handlers/base.py", line 197, in _get_response
    response = wrapped_callback(request, *callback_args, **callback_kwargs)
  File "/home/ubuntu/projects/JunBlog/main/view.py", line 26, in home
    posts = countpost(request)
  File "/home/ubuntu/projects/JunBlog/main/view.py", line 10, in countpost
    if request.user in User.objects.all(): # 유저가 로그인하면
  File "/home/ubuntu/venvs/myproject/lib/python3.8/site-packages/django/db/models/query.py", line 398, in __iter__
    self._fetch_all()
  File "/home/ubuntu/venvs/myproject/lib/python3.8/site-packages/django/db/models/query.py", line 1881, in _fetch_all
    self._result_cache = list(self._iterable_class(self))
  File "/home/ubuntu/venvs/myproject/lib/python3.8/site-packages/django/db/models/query.py", line 91, in __iter__
    results = compiler.execute_sql(
  File "/home/ubuntu/venvs/myproject/lib/python3.8/site-packages/django/db/models/sql/compiler.py", line 1560, in execute_sql
    cursor.execute(sql, params)
  File "/home/ubuntu/venvs/myproject/lib/python3.8/site-packages/django/db/backends/utils.py", line 67, in execute
    return self._execute_with_wrappers(
  File "/home/ubuntu/venvs/myproject/lib/python3.8/site-packages/django/db/backends/utils.py", line 80, in _execute_with_wrappers
    return executor(sql, params, many, context)
  File "/home/ubuntu/venvs/myproject/lib/python3.8/site-packages/django/db/backends/utils.py", line 89, in _execute
    return self.cursor.execute(sql, params)
  File "/home/ubuntu/venvs/myproject/lib/python3.8/site-packages/django/db/utils.py", line 91, in __exit__
    raise dj_exc_value.with_traceback(traceback) from exc_value
  File "/home/ubuntu/venvs/myproject/lib/python3.8/site-packages/django/db/backends/utils.py", line 89, in _execute
    return self.cursor.execute(sql, params)
  File "/home/ubuntu/venvs/myproject/lib/python3.8/site-packages/django/db/backends/sqlite3/base.py", line 328, in execute
    return super().execute(query, params)
django.db.utils.OperationalError: no such table: auth_user
2023-05-05 22:07:32,038 [INFO] junblog: INFO 레벨로 출력
2023-05-05 22:07:32,039 [ERROR] django.request: Internal Server Error: /
Traceback (most recent call last):
  File "/home/ubuntu/venvs/myproject/lib/python3.8/site-packages/django/db/backends/utils.py", line 89, in _execute
    return self.cursor.execute(sql, params)
  File "/home/ubuntu/venvs/myproject/lib/python3.8/site-packages/django/db/backends/sqlite3/base.py", line 328, in execute
    return super().execute(query, params)
sqlite3.OperationalError: no such table: auth_user

The above exception was the direct cause of the following exception:

Traceback (most recent call last):
  File "/home/ubuntu/venvs/myproject/lib/python3.8/site-packages/django/core/handlers/exception.py", line 55, in inner
    response = get_response(request)
  File "/home/ubuntu/venvs/myproject/lib/python3.8/site-packages/django/core/handlers/base.py", line 197, in _get_response
    response = wrapped_callback(request, *callback_args, **callback_kwargs)
  File "/home/ubuntu/projects/JunBlog/main/view.py", line 26, in home
    posts = countpost(request)
  File "/home/ubuntu/projects/JunBlog/main/view.py", line 10, in countpost
    if request.user in User.objects.all(): # 유저가 로그인하면
  File "/home/ubuntu/venvs/myproject/lib/python3.8/site-packages/django/db/models/query.py", line 398, in __iter__
    self._fetch_all()
  File "/home/ubuntu/venvs/myproject/lib/python3.8/site-packages/django/db/models/query.py", line 1881, in _fetch_all
    self._result_cache = list(self._iterable_class(self))
  File "/home/ubuntu/venvs/myproject/lib/python3.8/site-packages/django/db/models/query.py", line 91, in __iter__
    results = compiler.execute_sql(
  File "/home/ubuntu/venvs/myproject/lib/python3.8/site-packages/django/db/models/sql/compiler.py", line 1560, in execute_sql
    cursor.execute(sql, params)
  File "/home/ubuntu/venvs/myproject/lib/python3.8/site-packages/django/db/backends/utils.py", line 67, in execute
    return self._execute_with_wrappers(
  File "/home/ubuntu/venvs/myproject/lib/python3.8/site-packages/django/db/backends/utils.py", line 80, in _execute_with_wrappers
    return executor(sql, params, many, context)
  File "/home/ubuntu/venvs/myproject/lib/python3.8/site-packages/django/db/backends/utils.py", line 89, in _execute
    return self.cursor.execute(sql, params)
  File "/home/ubuntu/venvs/myproject/lib/python3.8/site-packages/django/db/utils.py", line 91, in __exit__
    raise dj_exc_value.with_traceback(traceback) from exc_value
  File "/home/ubuntu/venvs/myproject/lib/python3.8/site-packages/django/db/backends/utils.py", line 89, in _execute
    return self.cursor.execute(sql, params)
  File "/home/ubuntu/venvs/myproject/lib/python3.8/site-packages/django/db/backends/sqlite3/base.py", line 328, in execute
    return super().execute(query, params)
django.db.utils.OperationalError: no such table: auth_user
2023-05-05 22:07:32,225 [INFO] junblog: INFO 레벨로 출력
2023-05-05 22:07:32,226 [ERROR] django.request: Internal Server Error: /
Traceback (most recent call last):
  File "/home/ubuntu/venvs/myproject/lib/python3.8/site-packages/django/db/backends/utils.py", line 89, in _execute
    return self.cursor.execute(sql, params)
  File "/home/ubuntu/venvs/myproject/lib/python3.8/site-packages/django/db/backends/sqlite3/base.py", line 328, in execute
    return super().execute(query, params)
sqlite3.OperationalError: no such table: auth_user

The above exception was the direct cause of the following exception:

Traceback (most recent call last):
  File "/home/ubuntu/venvs/myproject/lib/python3.8/site-packages/django/core/handlers/exception.py", line 55, in inner
    response = get_response(request)
  File "/home/ubuntu/venvs/myproject/lib/python3.8/site-packages/django/core/handlers/base.py", line 197, in _get_response
    response = wrapped_callback(request, *callback_args, **callback_kwargs)
  File "/home/ubuntu/projects/JunBlog/main/view.py", line 26, in home
    posts = countpost(request)
  File "/home/ubuntu/projects/JunBlog/main/view.py", line 10, in countpost
    if request.user in User.objects.all(): # 유저가 로그인하면
  File "/home/ubuntu/venvs/myproject/lib/python3.8/site-packages/django/db/models/query.py", line 398, in __iter__
    self._fetch_all()
  File "/home/ubuntu/venvs/myproject/lib/python3.8/site-packages/django/db/models/query.py", line 1881, in _fetch_all
    self._result_cache = list(self._iterable_class(self))
  File "/home/ubuntu/venvs/myproject/lib/python3.8/site-packages/django/db/models/query.py", line 91, in __iter__
    results = compiler.execute_sql(
  File "/home/ubuntu/venvs/myproject/lib/python3.8/site-packages/django/db/models/sql/compiler.py", line 1560, in execute_sql
    cursor.execute(sql, params)
  File "/home/ubuntu/venvs/myproject/lib/python3.8/site-packages/django/db/backends/utils.py", line 67, in execute
    return self._execute_with_wrappers(
  File "/home/ubuntu/venvs/myproject/lib/python3.8/site-packages/django/db/backends/utils.py", line 80, in _execute_with_wrappers
    return executor(sql, params, many, context)
  File "/home/ubuntu/venvs/myproject/lib/python3.8/site-packages/django/db/backends/utils.py", line 89, in _execute
    return self.cursor.execute(sql, params)
  File "/home/ubuntu/venvs/myproject/lib/python3.8/site-packages/django/db/utils.py", line 91, in __exit__
    raise dj_exc_value.with_traceback(traceback) from exc_value
  File "/home/ubuntu/venvs/myproject/lib/python3.8/site-packages/django/db/backends/utils.py", line 89, in _execute
    return self.cursor.execute(sql, params)
  File "/home/ubuntu/venvs/myproject/lib/python3.8/site-packages/django/db/backends/sqlite3/base.py", line 328, in execute
    return super().execute(query, params)
django.db.utils.OperationalError: no such table: auth_user
2023-05-05 22:07:32,391 [INFO] junblog: INFO 레벨로 출력
2023-05-05 22:07:32,392 [ERROR] django.request: Internal Server Error: /
Traceback (most recent call last):
  File "/home/ubuntu/venvs/myproject/lib/python3.8/site-packages/django/db/backends/utils.py", line 89, in _execute
    return self.cursor.execute(sql, params)
  File "/home/ubuntu/venvs/myproject/lib/python3.8/site-packages/django/db/backends/sqlite3/base.py", line 328, in execute
    return super().execute(query, params)
sqlite3.OperationalError: no such table: auth_user

The above exception was the direct cause of the following exception:

Traceback (most recent call last):
  File "/home/ubuntu/venvs/myproject/lib/python3.8/site-packages/django/core/handlers/exception.py", line 55, in inner
    response = get_response(request)
  File "/home/ubuntu/venvs/myproject/lib/python3.8/site-packages/django/core/handlers/base.py", line 197, in _get_response
    response = wrapped_callback(request, *callback_args, **callback_kwargs)
  File "/home/ubuntu/projects/JunBlog/main/view.py", line 26, in home
    posts = countpost(request)
  File "/home/ubuntu/projects/JunBlog/main/view.py", line 10, in countpost
    if request.user in User.objects.all(): # 유저가 로그인하면
  File "/home/ubuntu/venvs/myproject/lib/python3.8/site-packages/django/db/models/query.py", line 398, in __iter__
    self._fetch_all()
  File "/home/ubuntu/venvs/myproject/lib/python3.8/site-packages/django/db/models/query.py", line 1881, in _fetch_all
    self._result_cache = list(self._iterable_class(self))
  File "/home/ubuntu/venvs/myproject/lib/python3.8/site-packages/django/db/models/query.py", line 91, in __iter__
    results = compiler.execute_sql(
  File "/home/ubuntu/venvs/myproject/lib/python3.8/site-packages/django/db/models/sql/compiler.py", line 1560, in execute_sql
    cursor.execute(sql, params)
  File "/home/ubuntu/venvs/myproject/lib/python3.8/site-packages/django/db/backends/utils.py", line 67, in execute
    return self._execute_with_wrappers(
  File "/home/ubuntu/venvs/myproject/lib/python3.8/site-packages/django/db/backends/utils.py", line 80, in _execute_with_wrappers
    return executor(sql, params, many, context)
  File "/home/ubuntu/venvs/myproject/lib/python3.8/site-packages/django/db/backends/utils.py", line 89, in _execute
    return self.cursor.execute(sql, params)
  File "/home/ubuntu/venvs/myproject/lib/python3.8/site-packages/django/db/utils.py", line 91, in __exit__
    raise dj_exc_value.with_traceback(traceback) from exc_value
  File "/home/ubuntu/venvs/myproject/lib/python3.8/site-packages/django/db/backends/utils.py", line 89, in _execute
    return self.cursor.execute(sql, params)
  File "/home/ubuntu/venvs/myproject/lib/python3.8/site-packages/django/db/backends/sqlite3/base.py", line 328, in execute
    return super().execute(query, params)
django.db.utils.OperationalError: no such table: auth_user
2023-05-05 22:07:32,554 [INFO] junblog: INFO 레벨로 출력
2023-05-05 22:07:32,555 [ERROR] django.request: Internal Server Error: /
Traceback (most recent call last):
  File "/home/ubuntu/venvs/myproject/lib/python3.8/site-packages/django/db/backends/utils.py", line 89, in _execute
    return self.cursor.execute(sql, params)
  File "/home/ubuntu/venvs/myproject/lib/python3.8/site-packages/django/db/backends/sqlite3/base.py", line 328, in execute
    return super().execute(query, params)
sqlite3.OperationalError: no such table: auth_user

The above exception was the direct cause of the following exception:

Traceback (most recent call last):
  File "/home/ubuntu/venvs/myproject/lib/python3.8/site-packages/django/core/handlers/exception.py", line 55, in inner
    response = get_response(request)
  File "/home/ubuntu/venvs/myproject/lib/python3.8/site-packages/django/core/handlers/base.py", line 197, in _get_response
    response = wrapped_callback(request, *callback_args, **callback_kwargs)
  File "/home/ubuntu/projects/JunBlog/main/view.py", line 26, in home
    posts = countpost(request)
  File "/home/ubuntu/projects/JunBlog/main/view.py", line 10, in countpost
    if request.user in User.objects.all(): # 유저가 로그인하면
  File "/home/ubuntu/venvs/myproject/lib/python3.8/site-packages/django/db/models/query.py", line 398, in __iter__
    self._fetch_all()
  File "/home/ubuntu/venvs/myproject/lib/python3.8/site-packages/django/db/models/query.py", line 1881, in _fetch_all
    self._result_cache = list(self._iterable_class(self))
  File "/home/ubuntu/venvs/myproject/lib/python3.8/site-packages/django/db/models/query.py", line 91, in __iter__
    results = compiler.execute_sql(
  File "/home/ubuntu/venvs/myproject/lib/python3.8/site-packages/django/db/models/sql/compiler.py", line 1560, in execute_sql
    cursor.execute(sql, params)
  File "/home/ubuntu/venvs/myproject/lib/python3.8/site-packages/django/db/backends/utils.py", line 67, in execute
    return self._execute_with_wrappers(
  File "/home/ubuntu/venvs/myproject/lib/python3.8/site-packages/django/db/backends/utils.py", line 80, in _execute_with_wrappers
    return executor(sql, params, many, context)
  File "/home/ubuntu/venvs/myproject/lib/python3.8/site-packages/django/db/backends/utils.py", line 89, in _execute
    return self.cursor.execute(sql, params)
  File "/home/ubuntu/venvs/myproject/lib/python3.8/site-packages/django/db/utils.py", line 91, in __exit__
    raise dj_exc_value.with_traceback(traceback) from exc_value
  File "/home/ubuntu/venvs/myproject/lib/python3.8/site-packages/django/db/backends/utils.py", line 89, in _execute
    return self.cursor.execute(sql, params)
  File "/home/ubuntu/venvs/myproject/lib/python3.8/site-packages/django/db/backends/sqlite3/base.py", line 328, in execute
    return super().execute(query, params)
django.db.utils.OperationalError: no such table: auth_user
2023-05-05 22:07:32,714 [INFO] junblog: INFO 레벨로 출력
2023-05-05 22:07:32,715 [ERROR] django.request: Internal Server Error: /
Traceback (most recent call last):
  File "/home/ubuntu/venvs/myproject/lib/python3.8/site-packages/django/db/backends/utils.py", line 89, in _execute
    return self.cursor.execute(sql, params)
  File "/home/ubuntu/venvs/myproject/lib/python3.8/site-packages/django/db/backends/sqlite3/base.py", line 328, in execute
    return super().execute(query, params)
sqlite3.OperationalError: no such table: auth_user

The above exception was the direct cause of the following exception:

Traceback (most recent call last):
  File "/home/ubuntu/venvs/myproject/lib/python3.8/site-packages/django/core/handlers/exception.py", line 55, in inner
    response = get_response(request)
  File "/home/ubuntu/venvs/myproject/lib/python3.8/site-packages/django/core/handlers/base.py", line 197, in _get_response
    response = wrapped_callback(request, *callback_args, **callback_kwargs)
  File "/home/ubuntu/projects/JunBlog/main/view.py", line 26, in home
    posts = countpost(request)
  File "/home/ubuntu/projects/JunBlog/main/view.py", line 10, in countpost
    if request.user in User.objects.all(): # 유저가 로그인하면
  File "/home/ubuntu/venvs/myproject/lib/python3.8/site-packages/django/db/models/query.py", line 398, in __iter__
    self._fetch_all()
  File "/home/ubuntu/venvs/myproject/lib/python3.8/site-packages/django/db/models/query.py", line 1881, in _fetch_all
    self._result_cache = list(self._iterable_class(self))
  File "/home/ubuntu/venvs/myproject/lib/python3.8/site-packages/django/db/models/query.py", line 91, in __iter__
    results = compiler.execute_sql(
  File "/home/ubuntu/venvs/myproject/lib/python3.8/site-packages/django/db/models/sql/compiler.py", line 1560, in execute_sql
    cursor.execute(sql, params)
  File "/home/ubuntu/venvs/myproject/lib/python3.8/site-packages/django/db/backends/utils.py", line 67, in execute
    return self._execute_with_wrappers(
  File "/home/ubuntu/venvs/myproject/lib/python3.8/site-packages/django/db/backends/utils.py", line 80, in _execute_with_wrappers
    return executor(sql, params, many, context)
  File "/home/ubuntu/venvs/myproject/lib/python3.8/site-packages/django/db/backends/utils.py", line 89, in _execute
    return self.cursor.execute(sql, params)
  File "/home/ubuntu/venvs/myproject/lib/python3.8/site-packages/django/db/utils.py", line 91, in __exit__
    raise dj_exc_value.with_traceback(traceback) from exc_value
  File "/home/ubuntu/venvs/myproject/lib/python3.8/site-packages/django/db/backends/utils.py", line 89, in _execute
    return self.cursor.execute(sql, params)
  File "/home/ubuntu/venvs/myproject/lib/python3.8/site-packages/django/db/backends/sqlite3/base.py", line 328, in execute
    return super().execute(query, params)
django.db.utils.OperationalError: no such table: auth_user
2023-05-05 22:07:52,035 [ERROR] django.request: Internal Server Error: /blog/
Traceback (most recent call last):
  File "/home/ubuntu/venvs/myproject/lib/python3.8/site-packages/django/db/backends/utils.py", line 89, in _execute
    return self.cursor.execute(sql, params)
  File "/home/ubuntu/venvs/myproject/lib/python3.8/site-packages/django/db/backends/sqlite3/base.py", line 328, in execute
    return super().execute(query, params)
sqlite3.OperationalError: no such table: auth_user

The above exception was the direct cause of the following exception:

Traceback (most recent call last):
  File "/home/ubuntu/venvs/myproject/lib/python3.8/site-packages/django/core/handlers/exception.py", line 55, in inner
    response = get_response(request)
  File "/home/ubuntu/venvs/myproject/lib/python3.8/site-packages/django/core/handlers/base.py", line 197, in _get_response
    response = wrapped_callback(request, *callback_args, **callback_kwargs)
  File "/home/ubuntu/projects/JunBlog/blog/views.py", line 31, in bloghome
    posts = countpost(request)
  File "/home/ubuntu/projects/JunBlog/blog/views.py", line 16, in countpost
    if request.user in User.objects.all(): # 유저가 로그인하면
  File "/home/ubuntu/venvs/myproject/lib/python3.8/site-packages/django/db/models/query.py", line 398, in __iter__
    self._fetch_all()
  File "/home/ubuntu/venvs/myproject/lib/python3.8/site-packages/django/db/models/query.py", line 1881, in _fetch_all
    self._result_cache = list(self._iterable_class(self))
  File "/home/ubuntu/venvs/myproject/lib/python3.8/site-packages/django/db/models/query.py", line 91, in __iter__
    results = compiler.execute_sql(
  File "/home/ubuntu/venvs/myproject/lib/python3.8/site-packages/django/db/models/sql/compiler.py", line 1560, in execute_sql
    cursor.execute(sql, params)
  File "/home/ubuntu/venvs/myproject/lib/python3.8/site-packages/django/db/backends/utils.py", line 67, in execute
    return self._execute_with_wrappers(
  File "/home/ubuntu/venvs/myproject/lib/python3.8/site-packages/django/db/backends/utils.py", line 80, in _execute_with_wrappers
    return executor(sql, params, many, context)
  File "/home/ubuntu/venvs/myproject/lib/python3.8/site-packages/django/db/backends/utils.py", line 89, in _execute
    return self.cursor.execute(sql, params)
  File "/home/ubuntu/venvs/myproject/lib/python3.8/site-packages/django/db/utils.py", line 91, in __exit__
    raise dj_exc_value.with_traceback(traceback) from exc_value
  File "/home/ubuntu/venvs/myproject/lib/python3.8/site-packages/django/db/backends/utils.py", line 89, in _execute
    return self.cursor.execute(sql, params)
  File "/home/ubuntu/venvs/myproject/lib/python3.8/site-packages/django/db/backends/sqlite3/base.py", line 328, in execute
    return super().execute(query, params)
django.db.utils.OperationalError: no such table: auth_user
2023-05-05 22:08:56,300 [INFO] junblog: INFO 레벨로 출력
2023-05-05 22:08:56,313 [ERROR] django.request: Internal Server Error: /
Traceback (most recent call last):
  File "/home/ubuntu/venvs/myproject/lib/python3.8/site-packages/django/db/backends/utils.py", line 89, in _execute
    return self.cursor.execute(sql, params)
  File "/home/ubuntu/venvs/myproject/lib/python3.8/site-packages/django/db/backends/sqlite3/base.py", line 328, in execute
    return super().execute(query, params)
sqlite3.OperationalError: no such table: auth_user

The above exception was the direct cause of the following exception:

Traceback (most recent call last):
  File "/home/ubuntu/venvs/myproject/lib/python3.8/site-packages/django/core/handlers/exception.py", line 55, in inner
    response = get_response(request)
  File "/home/ubuntu/venvs/myproject/lib/python3.8/site-packages/django/core/handlers/base.py", line 197, in _get_response
    response = wrapped_callback(request, *callback_args, **callback_kwargs)
  File "/home/ubuntu/projects/JunBlog/main/view.py", line 26, in home
    posts = countpost(request)
  File "/home/ubuntu/projects/JunBlog/main/view.py", line 10, in countpost
    if request.user in User.objects.all(): # 유저가 로그인하면
  File "/home/ubuntu/venvs/myproject/lib/python3.8/site-packages/django/db/models/query.py", line 398, in __iter__
    self._fetch_all()
  File "/home/ubuntu/venvs/myproject/lib/python3.8/site-packages/django/db/models/query.py", line 1881, in _fetch_all
    self._result_cache = list(self._iterable_class(self))
  File "/home/ubuntu/venvs/myproject/lib/python3.8/site-packages/django/db/models/query.py", line 91, in __iter__
    results = compiler.execute_sql(
  File "/home/ubuntu/venvs/myproject/lib/python3.8/site-packages/django/db/models/sql/compiler.py", line 1560, in execute_sql
    cursor.execute(sql, params)
  File "/home/ubuntu/venvs/myproject/lib/python3.8/site-packages/django/db/backends/utils.py", line 67, in execute
    return self._execute_with_wrappers(
  File "/home/ubuntu/venvs/myproject/lib/python3.8/site-packages/django/db/backends/utils.py", line 80, in _execute_with_wrappers
    return executor(sql, params, many, context)
  File "/home/ubuntu/venvs/myproject/lib/python3.8/site-packages/django/db/backends/utils.py", line 89, in _execute
    return self.cursor.execute(sql, params)
  File "/home/ubuntu/venvs/myproject/lib/python3.8/site-packages/django/db/utils.py", line 91, in __exit__
    raise dj_exc_value.with_traceback(traceback) from exc_value
  File "/home/ubuntu/venvs/myproject/lib/python3.8/site-packages/django/db/backends/utils.py", line 89, in _execute
    return self.cursor.execute(sql, params)
  File "/home/ubuntu/venvs/myproject/lib/python3.8/site-packages/django/db/backends/sqlite3/base.py", line 328, in execute
    return super().execute(query, params)
django.db.utils.OperationalError: no such table: auth_user
2023-05-05 22:08:57,094 [INFO] junblog: INFO 레벨로 출력
2023-05-05 22:08:57,107 [ERROR] django.request: Internal Server Error: /
Traceback (most recent call last):
  File "/home/ubuntu/venvs/myproject/lib/python3.8/site-packages/django/db/backends/utils.py", line 89, in _execute
    return self.cursor.execute(sql, params)
  File "/home/ubuntu/venvs/myproject/lib/python3.8/site-packages/django/db/backends/sqlite3/base.py", line 328, in execute
    return super().execute(query, params)
sqlite3.OperationalError: no such table: auth_user

The above exception was the direct cause of the following exception:

Traceback (most recent call last):
  File "/home/ubuntu/venvs/myproject/lib/python3.8/site-packages/django/core/handlers/exception.py", line 55, in inner
    response = get_response(request)
  File "/home/ubuntu/venvs/myproject/lib/python3.8/site-packages/django/core/handlers/base.py", line 197, in _get_response
    response = wrapped_callback(request, *callback_args, **callback_kwargs)
  File "/home/ubuntu/projects/JunBlog/main/view.py", line 26, in home
    posts = countpost(request)
  File "/home/ubuntu/projects/JunBlog/main/view.py", line 10, in countpost
    if request.user in User.objects.all(): # 유저가 로그인하면
  File "/home/ubuntu/venvs/myproject/lib/python3.8/site-packages/django/db/models/query.py", line 398, in __iter__
    self._fetch_all()
  File "/home/ubuntu/venvs/myproject/lib/python3.8/site-packages/django/db/models/query.py", line 1881, in _fetch_all
    self._result_cache = list(self._iterable_class(self))
  File "/home/ubuntu/venvs/myproject/lib/python3.8/site-packages/django/db/models/query.py", line 91, in __iter__
    results = compiler.execute_sql(
  File "/home/ubuntu/venvs/myproject/lib/python3.8/site-packages/django/db/models/sql/compiler.py", line 1560, in execute_sql
    cursor.execute(sql, params)
  File "/home/ubuntu/venvs/myproject/lib/python3.8/site-packages/django/db/backends/utils.py", line 67, in execute
    return self._execute_with_wrappers(
  File "/home/ubuntu/venvs/myproject/lib/python3.8/site-packages/django/db/backends/utils.py", line 80, in _execute_with_wrappers
    return executor(sql, params, many, context)
  File "/home/ubuntu/venvs/myproject/lib/python3.8/site-packages/django/db/backends/utils.py", line 89, in _execute
    return self.cursor.execute(sql, params)
  File "/home/ubuntu/venvs/myproject/lib/python3.8/site-packages/django/db/utils.py", line 91, in __exit__
    raise dj_exc_value.with_traceback(traceback) from exc_value
  File "/home/ubuntu/venvs/myproject/lib/python3.8/site-packages/django/db/backends/utils.py", line 89, in _execute
    return self.cursor.execute(sql, params)
  File "/home/ubuntu/venvs/myproject/lib/python3.8/site-packages/django/db/backends/sqlite3/base.py", line 328, in execute
    return super().execute(query, params)
django.db.utils.OperationalError: no such table: auth_user
2023-05-05 22:09:51,710 [INFO] junblog: INFO 레벨로 출력
2023-05-05 22:09:51,722 [ERROR] django.request: Internal Server Error: /
Traceback (most recent call last):
  File "/home/ubuntu/venvs/myproject/lib/python3.8/site-packages/django/db/backends/utils.py", line 89, in _execute
    return self.cursor.execute(sql, params)
  File "/home/ubuntu/venvs/myproject/lib/python3.8/site-packages/django/db/backends/sqlite3/base.py", line 328, in execute
    return super().execute(query, params)
sqlite3.OperationalError: no such table: auth_user

The above exception was the direct cause of the following exception:

Traceback (most recent call last):
  File "/home/ubuntu/venvs/myproject/lib/python3.8/site-packages/django/core/handlers/exception.py", line 55, in inner
    response = get_response(request)
  File "/home/ubuntu/venvs/myproject/lib/python3.8/site-packages/django/core/handlers/base.py", line 197, in _get_response
    response = wrapped_callback(request, *callback_args, **callback_kwargs)
  File "/home/ubuntu/projects/JunBlog/main/view.py", line 26, in home
    posts = countpost(request)
  File "/home/ubuntu/projects/JunBlog/main/view.py", line 10, in countpost
    if request.user in User.objects.all(): # 유저가 로그인하면
  File "/home/ubuntu/venvs/myproject/lib/python3.8/site-packages/django/db/models/query.py", line 398, in __iter__
    self._fetch_all()
  File "/home/ubuntu/venvs/myproject/lib/python3.8/site-packages/django/db/models/query.py", line 1881, in _fetch_all
    self._result_cache = list(self._iterable_class(self))
  File "/home/ubuntu/venvs/myproject/lib/python3.8/site-packages/django/db/models/query.py", line 91, in __iter__
    results = compiler.execute_sql(
  File "/home/ubuntu/venvs/myproject/lib/python3.8/site-packages/django/db/models/sql/compiler.py", line 1560, in execute_sql
    cursor.execute(sql, params)
  File "/home/ubuntu/venvs/myproject/lib/python3.8/site-packages/django/db/backends/utils.py", line 67, in execute
    return self._execute_with_wrappers(
  File "/home/ubuntu/venvs/myproject/lib/python3.8/site-packages/django/db/backends/utils.py", line 80, in _execute_with_wrappers
    return executor(sql, params, many, context)
  File "/home/ubuntu/venvs/myproject/lib/python3.8/site-packages/django/db/backends/utils.py", line 89, in _execute
    return self.cursor.execute(sql, params)
  File "/home/ubuntu/venvs/myproject/lib/python3.8/site-packages/django/db/utils.py", line 91, in __exit__
    raise dj_exc_value.with_traceback(traceback) from exc_value
  File "/home/ubuntu/venvs/myproject/lib/python3.8/site-packages/django/db/backends/utils.py", line 89, in _execute
    return self.cursor.execute(sql, params)
  File "/home/ubuntu/venvs/myproject/lib/python3.8/site-packages/django/db/backends/sqlite3/base.py", line 328, in execute
    return super().execute(query, params)
django.db.utils.OperationalError: no such table: auth_user
2023-05-05 22:09:52,982 [INFO] junblog: INFO 레벨로 출력
2023-05-05 22:09:52,994 [ERROR] django.request: Internal Server Error: /
Traceback (most recent call last):
  File "/home/ubuntu/venvs/myproject/lib/python3.8/site-packages/django/db/backends/utils.py", line 89, in _execute
    return self.cursor.execute(sql, params)
  File "/home/ubuntu/venvs/myproject/lib/python3.8/site-packages/django/db/backends/sqlite3/base.py", line 328, in execute
    return super().execute(query, params)
sqlite3.OperationalError: no such table: auth_user

The above exception was the direct cause of the following exception:

Traceback (most recent call last):
  File "/home/ubuntu/venvs/myproject/lib/python3.8/site-packages/django/core/handlers/exception.py", line 55, in inner
    response = get_response(request)
  File "/home/ubuntu/venvs/myproject/lib/python3.8/site-packages/django/core/handlers/base.py", line 197, in _get_response
    response = wrapped_callback(request, *callback_args, **callback_kwargs)
  File "/home/ubuntu/projects/JunBlog/main/view.py", line 26, in home
    posts = countpost(request)
  File "/home/ubuntu/projects/JunBlog/main/view.py", line 10, in countpost
    if request.user in User.objects.all(): # 유저가 로그인하면
  File "/home/ubuntu/venvs/myproject/lib/python3.8/site-packages/django/db/models/query.py", line 398, in __iter__
    self._fetch_all()
  File "/home/ubuntu/venvs/myproject/lib/python3.8/site-packages/django/db/models/query.py", line 1881, in _fetch_all
    self._result_cache = list(self._iterable_class(self))
  File "/home/ubuntu/venvs/myproject/lib/python3.8/site-packages/django/db/models/query.py", line 91, in __iter__
    results = compiler.execute_sql(
  File "/home/ubuntu/venvs/myproject/lib/python3.8/site-packages/django/db/models/sql/compiler.py", line 1560, in execute_sql
    cursor.execute(sql, params)
  File "/home/ubuntu/venvs/myproject/lib/python3.8/site-packages/django/db/backends/utils.py", line 67, in execute
    return self._execute_with_wrappers(
  File "/home/ubuntu/venvs/myproject/lib/python3.8/site-packages/django/db/backends/utils.py", line 80, in _execute_with_wrappers
    return executor(sql, params, many, context)
  File "/home/ubuntu/venvs/myproject/lib/python3.8/site-packages/django/db/backends/utils.py", line 89, in _execute
    return self.cursor.execute(sql, params)
  File "/home/ubuntu/venvs/myproject/lib/python3.8/site-packages/django/db/utils.py", line 91, in __exit__
    raise dj_exc_value.with_traceback(traceback) from exc_value
  File "/home/ubuntu/venvs/myproject/lib/python3.8/site-packages/django/db/backends/utils.py", line 89, in _execute
    return self.cursor.execute(sql, params)
  File "/home/ubuntu/venvs/myproject/lib/python3.8/site-packages/django/db/backends/sqlite3/base.py", line 328, in execute
    return super().execute(query, params)
django.db.utils.OperationalError: no such table: auth_user
2023-05-05 22:09:56,073 [ERROR] django.request: Internal Server Error: /blog/
Traceback (most recent call last):
  File "/home/ubuntu/venvs/myproject/lib/python3.8/site-packages/django/db/backends/utils.py", line 89, in _execute
    return self.cursor.execute(sql, params)
  File "/home/ubuntu/venvs/myproject/lib/python3.8/site-packages/django/db/backends/sqlite3/base.py", line 328, in execute
    return super().execute(query, params)
sqlite3.OperationalError: no such table: auth_user

The above exception was the direct cause of the following exception:

Traceback (most recent call last):
  File "/home/ubuntu/venvs/myproject/lib/python3.8/site-packages/django/core/handlers/exception.py", line 55, in inner
    response = get_response(request)
  File "/home/ubuntu/venvs/myproject/lib/python3.8/site-packages/django/core/handlers/base.py", line 197, in _get_response
    response = wrapped_callback(request, *callback_args, **callback_kwargs)
  File "/home/ubuntu/projects/JunBlog/blog/views.py", line 31, in bloghome
    posts = countpost(request)
  File "/home/ubuntu/projects/JunBlog/blog/views.py", line 16, in countpost
    if request.user in User.objects.all(): # 유저가 로그인하면
  File "/home/ubuntu/venvs/myproject/lib/python3.8/site-packages/django/db/models/query.py", line 398, in __iter__
    self._fetch_all()
  File "/home/ubuntu/venvs/myproject/lib/python3.8/site-packages/django/db/models/query.py", line 1881, in _fetch_all
    self._result_cache = list(self._iterable_class(self))
  File "/home/ubuntu/venvs/myproject/lib/python3.8/site-packages/django/db/models/query.py", line 91, in __iter__
    results = compiler.execute_sql(
  File "/home/ubuntu/venvs/myproject/lib/python3.8/site-packages/django/db/models/sql/compiler.py", line 1560, in execute_sql
    cursor.execute(sql, params)
  File "/home/ubuntu/venvs/myproject/lib/python3.8/site-packages/django/db/backends/utils.py", line 67, in execute
    return self._execute_with_wrappers(
  File "/home/ubuntu/venvs/myproject/lib/python3.8/site-packages/django/db/backends/utils.py", line 80, in _execute_with_wrappers
    return executor(sql, params, many, context)
  File "/home/ubuntu/venvs/myproject/lib/python3.8/site-packages/django/db/backends/utils.py", line 89, in _execute
    return self.cursor.execute(sql, params)
  File "/home/ubuntu/venvs/myproject/lib/python3.8/site-packages/django/db/utils.py", line 91, in __exit__
    raise dj_exc_value.with_traceback(traceback) from exc_value
  File "/home/ubuntu/venvs/myproject/lib/python3.8/site-packages/django/db/backends/utils.py", line 89, in _execute
    return self.cursor.execute(sql, params)
  File "/home/ubuntu/venvs/myproject/lib/python3.8/site-packages/django/db/backends/sqlite3/base.py", line 328, in execute
    return super().execute(query, params)
django.db.utils.OperationalError: no such table: auth_user
2023-05-05 22:17:52,449 [INFO] junblog: INFO 레벨로 출력
2023-05-05 22:17:52,461 [ERROR] django.request: Internal Server Error: /
Traceback (most recent call last):
  File "/home/ubuntu/venvs/myproject/lib/python3.8/site-packages/django/db/backends/utils.py", line 89, in _execute
    return self.cursor.execute(sql, params)
  File "/home/ubuntu/venvs/myproject/lib/python3.8/site-packages/django/db/backends/sqlite3/base.py", line 328, in execute
    return super().execute(query, params)
sqlite3.OperationalError: no such table: auth_user

The above exception was the direct cause of the following exception:

Traceback (most recent call last):
  File "/home/ubuntu/venvs/myproject/lib/python3.8/site-packages/django/core/handlers/exception.py", line 55, in inner
    response = get_response(request)
  File "/home/ubuntu/venvs/myproject/lib/python3.8/site-packages/django/core/handlers/base.py", line 197, in _get_response
    response = wrapped_callback(request, *callback_args, **callback_kwargs)
  File "/home/ubuntu/projects/JunBlog/main/view.py", line 26, in home
    posts = countpost(request)
  File "/home/ubuntu/projects/JunBlog/main/view.py", line 10, in countpost
    if request.user in User.objects.all(): # 유저가 로그인하면
  File "/home/ubuntu/venvs/myproject/lib/python3.8/site-packages/django/db/models/query.py", line 398, in __iter__
    self._fetch_all()
  File "/home/ubuntu/venvs/myproject/lib/python3.8/site-packages/django/db/models/query.py", line 1881, in _fetch_all
    self._result_cache = list(self._iterable_class(self))
  File "/home/ubuntu/venvs/myproject/lib/python3.8/site-packages/django/db/models/query.py", line 91, in __iter__
    results = compiler.execute_sql(
  File "/home/ubuntu/venvs/myproject/lib/python3.8/site-packages/django/db/models/sql/compiler.py", line 1560, in execute_sql
    cursor.execute(sql, params)
  File "/home/ubuntu/venvs/myproject/lib/python3.8/site-packages/django/db/backends/utils.py", line 67, in execute
    return self._execute_with_wrappers(
  File "/home/ubuntu/venvs/myproject/lib/python3.8/site-packages/django/db/backends/utils.py", line 80, in _execute_with_wrappers
    return executor(sql, params, many, context)
  File "/home/ubuntu/venvs/myproject/lib/python3.8/site-packages/django/db/backends/utils.py", line 89, in _execute
    return self.cursor.execute(sql, params)
  File "/home/ubuntu/venvs/myproject/lib/python3.8/site-packages/django/db/utils.py", line 91, in __exit__
    raise dj_exc_value.with_traceback(traceback) from exc_value
  File "/home/ubuntu/venvs/myproject/lib/python3.8/site-packages/django/db/backends/utils.py", line 89, in _execute
    return self.cursor.execute(sql, params)
  File "/home/ubuntu/venvs/myproject/lib/python3.8/site-packages/django/db/backends/sqlite3/base.py", line 328, in execute
    return super().execute(query, params)
django.db.utils.OperationalError: no such table: auth_user
2023-05-05 22:28:43,415 [WARNING] django.security.csrf: Forbidden (CSRF cookie not set.): /
2023-05-05 22:30:53,781 [INFO] junblog: INFO 레벨로 출력
2023-05-05 22:30:53,793 [ERROR] django.request: Internal Server Error: /
Traceback (most recent call last):
  File "/home/ubuntu/venvs/myproject/lib/python3.8/site-packages/django/db/backends/utils.py", line 89, in _execute
    return self.cursor.execute(sql, params)
  File "/home/ubuntu/venvs/myproject/lib/python3.8/site-packages/django/db/backends/sqlite3/base.py", line 328, in execute
    return super().execute(query, params)
sqlite3.OperationalError: no such table: auth_user

The above exception was the direct cause of the following exception:

Traceback (most recent call last):
  File "/home/ubuntu/venvs/myproject/lib/python3.8/site-packages/django/core/handlers/exception.py", line 55, in inner
    response = get_response(request)
  File "/home/ubuntu/venvs/myproject/lib/python3.8/site-packages/django/core/handlers/base.py", line 197, in _get_response
    response = wrapped_callback(request, *callback_args, **callback_kwargs)
  File "/home/ubuntu/projects/JunBlog/main/view.py", line 26, in home
    posts = countpost(request)
  File "/home/ubuntu/projects/JunBlog/main/view.py", line 10, in countpost
    if request.user in User.objects.all(): # 유저가 로그인하면
  File "/home/ubuntu/venvs/myproject/lib/python3.8/site-packages/django/db/models/query.py", line 398, in __iter__
    self._fetch_all()
  File "/home/ubuntu/venvs/myproject/lib/python3.8/site-packages/django/db/models/query.py", line 1881, in _fetch_all
    self._result_cache = list(self._iterable_class(self))
  File "/home/ubuntu/venvs/myproject/lib/python3.8/site-packages/django/db/models/query.py", line 91, in __iter__
    results = compiler.execute_sql(
  File "/home/ubuntu/venvs/myproject/lib/python3.8/site-packages/django/db/models/sql/compiler.py", line 1560, in execute_sql
    cursor.execute(sql, params)
  File "/home/ubuntu/venvs/myproject/lib/python3.8/site-packages/django/db/backends/utils.py", line 67, in execute
    return self._execute_with_wrappers(
  File "/home/ubuntu/venvs/myproject/lib/python3.8/site-packages/django/db/backends/utils.py", line 80, in _execute_with_wrappers
    return executor(sql, params, many, context)
  File "/home/ubuntu/venvs/myproject/lib/python3.8/site-packages/django/db/backends/utils.py", line 89, in _execute
    return self.cursor.execute(sql, params)
  File "/home/ubuntu/venvs/myproject/lib/python3.8/site-packages/django/db/utils.py", line 91, in __exit__
    raise dj_exc_value.with_traceback(traceback) from exc_value
  File "/home/ubuntu/venvs/myproject/lib/python3.8/site-packages/django/db/backends/utils.py", line 89, in _execute
    return self.cursor.execute(sql, params)
  File "/home/ubuntu/venvs/myproject/lib/python3.8/site-packages/django/db/backends/sqlite3/base.py", line 328, in execute
    return super().execute(query, params)
django.db.utils.OperationalError: no such table: auth_user
2023-05-05 22:30:54,087 [INFO] junblog: INFO 레벨로 출력
2023-05-05 22:30:54,100 [ERROR] django.request: Internal Server Error: /
Traceback (most recent call last):
  File "/home/ubuntu/venvs/myproject/lib/python3.8/site-packages/django/db/backends/utils.py", line 89, in _execute
    return self.cursor.execute(sql, params)
  File "/home/ubuntu/venvs/myproject/lib/python3.8/site-packages/django/db/backends/sqlite3/base.py", line 328, in execute
    return super().execute(query, params)
sqlite3.OperationalError: no such table: auth_user

The above exception was the direct cause of the following exception:

Traceback (most recent call last):
  File "/home/ubuntu/venvs/myproject/lib/python3.8/site-packages/django/core/handlers/exception.py", line 55, in inner
    response = get_response(request)
  File "/home/ubuntu/venvs/myproject/lib/python3.8/site-packages/django/core/handlers/base.py", line 197, in _get_response
    response = wrapped_callback(request, *callback_args, **callback_kwargs)
  File "/home/ubuntu/projects/JunBlog/main/view.py", line 26, in home
    posts = countpost(request)
  File "/home/ubuntu/projects/JunBlog/main/view.py", line 10, in countpost
    if request.user in User.objects.all(): # 유저가 로그인하면
  File "/home/ubuntu/venvs/myproject/lib/python3.8/site-packages/django/db/models/query.py", line 398, in __iter__
    self._fetch_all()
  File "/home/ubuntu/venvs/myproject/lib/python3.8/site-packages/django/db/models/query.py", line 1881, in _fetch_all
    self._result_cache = list(self._iterable_class(self))
  File "/home/ubuntu/venvs/myproject/lib/python3.8/site-packages/django/db/models/query.py", line 91, in __iter__
    results = compiler.execute_sql(
  File "/home/ubuntu/venvs/myproject/lib/python3.8/site-packages/django/db/models/sql/compiler.py", line 1560, in execute_sql
    cursor.execute(sql, params)
  File "/home/ubuntu/venvs/myproject/lib/python3.8/site-packages/django/db/backends/utils.py", line 67, in execute
    return self._execute_with_wrappers(
  File "/home/ubuntu/venvs/myproject/lib/python3.8/site-packages/django/db/backends/utils.py", line 80, in _execute_with_wrappers
    return executor(sql, params, many, context)
  File "/home/ubuntu/venvs/myproject/lib/python3.8/site-packages/django/db/backends/utils.py", line 89, in _execute
    return self.cursor.execute(sql, params)
  File "/home/ubuntu/venvs/myproject/lib/python3.8/site-packages/django/db/utils.py", line 91, in __exit__
    raise dj_exc_value.with_traceback(traceback) from exc_value
  File "/home/ubuntu/venvs/myproject/lib/python3.8/site-packages/django/db/backends/utils.py", line 89, in _execute
    return self.cursor.execute(sql, params)
  File "/home/ubuntu/venvs/myproject/lib/python3.8/site-packages/django/db/backends/sqlite3/base.py", line 328, in execute
    return super().execute(query, params)
django.db.utils.OperationalError: no such table: auth_user
2023-05-05 22:41:37,818 [INFO] junblog: INFO 레벨로 출력
2023-05-05 22:41:37,820 [ERROR] django.request: Internal Server Error: /
Traceback (most recent call last):
  File "/home/ubuntu/venvs/myproject/lib/python3.8/site-packages/django/db/backends/utils.py", line 89, in _execute
    return self.cursor.execute(sql, params)
  File "/home/ubuntu/venvs/myproject/lib/python3.8/site-packages/django/db/backends/sqlite3/base.py", line 328, in execute
    return super().execute(query, params)
sqlite3.OperationalError: no such table: auth_user

The above exception was the direct cause of the following exception:

Traceback (most recent call last):
  File "/home/ubuntu/venvs/myproject/lib/python3.8/site-packages/django/core/handlers/exception.py", line 55, in inner
    response = get_response(request)
  File "/home/ubuntu/venvs/myproject/lib/python3.8/site-packages/django/core/handlers/base.py", line 197, in _get_response
    response = wrapped_callback(request, *callback_args, **callback_kwargs)
  File "/home/ubuntu/projects/JunBlog/main/view.py", line 26, in home
    posts = countpost(request)
  File "/home/ubuntu/projects/JunBlog/main/view.py", line 10, in countpost
    if request.user in User.objects.all(): # 유저가 로그인하면
  File "/home/ubuntu/venvs/myproject/lib/python3.8/site-packages/django/db/models/query.py", line 398, in __iter__
    self._fetch_all()
  File "/home/ubuntu/venvs/myproject/lib/python3.8/site-packages/django/db/models/query.py", line 1881, in _fetch_all
    self._result_cache = list(self._iterable_class(self))
  File "/home/ubuntu/venvs/myproject/lib/python3.8/site-packages/django/db/models/query.py", line 91, in __iter__
    results = compiler.execute_sql(
  File "/home/ubuntu/venvs/myproject/lib/python3.8/site-packages/django/db/models/sql/compiler.py", line 1560, in execute_sql
    cursor.execute(sql, params)
  File "/home/ubuntu/venvs/myproject/lib/python3.8/site-packages/django/db/backends/utils.py", line 67, in execute
    return self._execute_with_wrappers(
  File "/home/ubuntu/venvs/myproject/lib/python3.8/site-packages/django/db/backends/utils.py", line 80, in _execute_with_wrappers
    return executor(sql, params, many, context)
  File "/home/ubuntu/venvs/myproject/lib/python3.8/site-packages/django/db/backends/utils.py", line 89, in _execute
    return self.cursor.execute(sql, params)
  File "/home/ubuntu/venvs/myproject/lib/python3.8/site-packages/django/db/utils.py", line 91, in __exit__
    raise dj_exc_value.with_traceback(traceback) from exc_value
  File "/home/ubuntu/venvs/myproject/lib/python3.8/site-packages/django/db/backends/utils.py", line 89, in _execute
    return self.cursor.execute(sql, params)
  File "/home/ubuntu/venvs/myproject/lib/python3.8/site-packages/django/db/backends/sqlite3/base.py", line 328, in execute
    return super().execute(query, params)
django.db.utils.OperationalError: no such table: auth_user
2023-05-05 22:42:23,413 [INFO] junblog: INFO 레벨로 출력
2023-05-05 22:42:23,414 [ERROR] django.request: Internal Server Error: /
Traceback (most recent call last):
  File "/home/ubuntu/venvs/myproject/lib/python3.8/site-packages/django/db/backends/utils.py", line 89, in _execute
    return self.cursor.execute(sql, params)
  File "/home/ubuntu/venvs/myproject/lib/python3.8/site-packages/django/db/backends/sqlite3/base.py", line 328, in execute
    return super().execute(query, params)
sqlite3.OperationalError: no such table: auth_user

The above exception was the direct cause of the following exception:

Traceback (most recent call last):
  File "/home/ubuntu/venvs/myproject/lib/python3.8/site-packages/django/core/handlers/exception.py", line 55, in inner
    response = get_response(request)
  File "/home/ubuntu/venvs/myproject/lib/python3.8/site-packages/django/core/handlers/base.py", line 197, in _get_response
    response = wrapped_callback(request, *callback_args, **callback_kwargs)
  File "/home/ubuntu/projects/JunBlog/main/view.py", line 26, in home
    posts = countpost(request)
  File "/home/ubuntu/projects/JunBlog/main/view.py", line 10, in countpost
    if request.user in User.objects.all(): # 유저가 로그인하면
  File "/home/ubuntu/venvs/myproject/lib/python3.8/site-packages/django/db/models/query.py", line 398, in __iter__
    self._fetch_all()
  File "/home/ubuntu/venvs/myproject/lib/python3.8/site-packages/django/db/models/query.py", line 1881, in _fetch_all
    self._result_cache = list(self._iterable_class(self))
  File "/home/ubuntu/venvs/myproject/lib/python3.8/site-packages/django/db/models/query.py", line 91, in __iter__
    results = compiler.execute_sql(
  File "/home/ubuntu/venvs/myproject/lib/python3.8/site-packages/django/db/models/sql/compiler.py", line 1560, in execute_sql
    cursor.execute(sql, params)
  File "/home/ubuntu/venvs/myproject/lib/python3.8/site-packages/django/db/backends/utils.py", line 67, in execute
    return self._execute_with_wrappers(
  File "/home/ubuntu/venvs/myproject/lib/python3.8/site-packages/django/db/backends/utils.py", line 80, in _execute_with_wrappers
    return executor(sql, params, many, context)
  File "/home/ubuntu/venvs/myproject/lib/python3.8/site-packages/django/db/backends/utils.py", line 89, in _execute
    return self.cursor.execute(sql, params)
  File "/home/ubuntu/venvs/myproject/lib/python3.8/site-packages/django/db/utils.py", line 91, in __exit__
    raise dj_exc_value.with_traceback(traceback) from exc_value
  File "/home/ubuntu/venvs/myproject/lib/python3.8/site-packages/django/db/backends/utils.py", line 89, in _execute
    return self.cursor.execute(sql, params)
  File "/home/ubuntu/venvs/myproject/lib/python3.8/site-packages/django/db/backends/sqlite3/base.py", line 328, in execute
    return super().execute(query, params)
django.db.utils.OperationalError: no such table: auth_user
2023-05-05 22:49:17,639 [INFO] junblog: INFO 레벨로 출력
2023-05-05 22:54:31,550 [INFO] junblog: INFO 레벨로 출력
2023-05-05 22:54:51,378 [INFO] junblog: INFO 레벨로 출력
2023-05-05 22:55:14,700 [INFO] junblog: INFO 레벨로 출력
2023-05-05 22:55:16,967 [INFO] junblog: INFO 레벨로 출력
2023-05-05 22:55:26,739 [INFO] junblog: INFO 레벨로 출력
2023-05-05 22:55:29,016 [INFO] junblog: INFO 레벨로 출력
